Workbook
Name Actividad_fisica: 'Pediatría'!$L$55:$L$57
Name Actividad_fisica: 'Pediatría'!$L$55:$L$57
Name Z_EED67FAE_D7A7_442D_B29B_6BF40C688036_.wvu.Cols: 'Antropometría'!$E:$E

Sheet Inicio
B15: Bienvenid@, a continuación encontrará cada uno de los botones para ingresar a la sección de su interés. En caso de requerir ayuda comuníquese al correo evanut.app@gmail.com o a través de Whatsapp +57 300 2881395. Con la compra de EVANUT apoyas el sostenimiento estudiantil, te invitamos a ser una persona ética y honesta, evita compartir esta herramienta con otras personas.
H26: Evaluación de la composición corporal del adulto
H29: Evaluación del consumo de alimentos de un paciente, puede usar un R24h
H32: Fórmulas de requerimiento y planeación dietética del paciente adulto
H35: Evaluación de la composición corporal y planeación dietética del paciente pediátrico (0 a 18 años)
H38: Evaluación, seguimiento y planeación dietética de la gestante adulta
H41: Evaluación, seguimiento y planeación dietética de la gestante adolescente
H44: Estimación de peso y talla, determinación de requerimiento energético y de líquidos, fórmulas de nutrición parenteral en el adulto hospitalizado
H47: Evaluación de la composición corporal, somatocarta y planeación dietética del deportista
H50: Planeación dietética (solo fórmula desarrollada, fórmula sintética final, minuta patrón y ejemplo de menú) en pacientes de todas las edades
H53: Fórmulas de porcentaje de grasa de Durnin y Womersley, y Jackson y Pollock, de años anteriores y en diferentes grupos poblacionales
H56: Espacio para poner las notas que requiera frente al análisis del paciente que está tratando

Sheet Antropometría
B2: EVALUACIÓN ANTROPOMÉTRICA
B3: Nombre | E3: Hombre
B4: Apellido | E4: Mujer
B5: Identificación
B6: Sexo | C6: Hombre
B7: Edad años
B8: Peso kg
B9: Altura m
B10: Altura cm | C10: =C9*100 -> 0
B11: Perímetro cintura cm | F11: NOTA: El porcentaje de grasa se calcula automáticamente bajo la fórmula de Durnin y Womersley del 2011 para población hispana. En caso de requerir una diferente diríjase a la hoja "Otros".
B12: Perímetro abdomen cm
B13: Pliegue biceps mm
B14: Pliegue triceps mm
B15: Pliegue subescapular mm
B16: Pliegue ileocrestal mm | E16: =SUM(C13:C16) -> 0
B17: Pliegue muslo mm | F17: CLASIFICACIÓN % GRASA
G18: HOMBRES | H18: MUJERES
B19: RESULTADOS | F19: Normopeso | G19: 12-20 | H19: 20-30
B20: IMC | C20: =(C8/(C9*C9)) -> #DIV/0! | F20: Limite | G20: 21-25 | H20: 31-33
B21: IMC Clasificación | C21: =IF(C20<18.5,"Delgadez",IF(AND(C20>=18.5,C20<25),"Normal",IF(AND(C20>=25,C20<30),"Sobrepeso","obesidad"))) -> #DIV/0! | F21: Obesidad | G21: >25 | H21: >33
B22: IMC saludable | C22: 25
B23: Peso saludable IMC 25-30 | C23: =IF(C20>=25,(C22*(C9*C9)),"No aplica") -> #DIV/0! | F23: CLASIFICACIÓN IMG
B24: Peso ajustado IMC >30 | C24: =IF(C20>=30,(C23+(0.25*(C8-C23))),"No aplica") -> #DIV/0! | G24: HOMBRES | H24: MUJERES
B25: Cintura/Estatura | C25: =C11/C10 -> #DIV/0! | F25: Deficit | G25: <3 | H25: <5
B26: Clasificación | C26: =IF(C25>0.5,"Riesgo","Sin riesgo") -> #DIV/0! | F26: Normal | G26: 3-6 | H26: 5-9
B27: Cintura cm | C27: =C11 | F27: Exceso | G27: >6 | H27: >9
B28: Clasificación | C28: =IF(C6="Hombre",IF(C27>=90,"Obesidad abdominal","Adecuado"),IF(C27>=80,"Obesidad abdominal","Adecuado")) -> Adecuado
B29: %Grasa | C29: =IF(C6="Hombre",((23.66*(LOG10(E16)))+(0.04*C7)-(0.036*C8)-(0.109*C10)+(0.272*C12)-26.41),((23.871*(LOG10(E16)))+(0.019*C7)-(0.022*C8)-(0.118*C10)+(0.249*C12)-16.782)) -> #NUM! | F29: CLASIFICACIÓN IMLG
B30: Clasificación | C30: =IF(C6="Hombre",IF(C29<=20,"Normopeso",IF(AND(C29>20,C29<=25),"limite",IF(C29>25,"obesidad"))),IF(C29<=30,"Normopeso",IF(AND(C29>30,C29<=33),"limite",IF(C29>33,"obesidad")))) -> #NUM! | G30: HOMBRES | H30: MUJERES
B31: Masa grasa kg | C31: =C29%*C8 -> #NUM! | F31: Malnutricion | G31: <17 | H31: <15
B32: IMG | C32: =C31/(C9*C9) -> #NUM! | F32: Adecuada | G32: 17-21 | H32: 15-18 | J32: REFERENCIAS
B33: Clasificación | C33: =IF(C6="Hombre",IF(C32<2,"Deficit severo",IF(AND(C32>=2,C32<2.3),"Deficit moderado",IF(AND(C32>=2.3,C32<3),"Deficit leve",IF(AND(C32>=3,C32<=6),"Normal",IF(AND(C32>6,C32<=9),"Exceso",IF(AND(C32>9,C32<=12),"Obesidad I",IF(AND(C32>12,C32<=15),"Obesidad II","Obesidad III"))))))),IF(C32<3.5,"Deficit severo",IF(AND(C32>=3.5,C32<4),"Deficit moderado",IF(AND(C32>=4,C32<5),"Deficit leve",IF(AND(C32>=5,C32<=9),"Normal",IF(AND(C32>9,C32<=13),"Exceso",IF(AND(C32>13,C32<=17),"Obesidad I",IF(AND(C32>17,C32<=21),"Obesidad II","Obesidad III")))))))) -> #NUM! | F33: Muy buena | G33: >21 | H33: >18 | J33: IMC: Res 2465 de 2016 Ministerio de salud y proteccion social
B34: Masa libre de grasa kg | C34: =C8-C31 -> #NUM! | J34: Cintura/Estatura: Browning LM, Hsieh SD, Ashwell M. A systematic review of waist-to-height ratio as a screening tool for the prediction of cardiovascular disease and diabetes: 0·5 could be a suitable global boundary value. Nutr Res Rev. 2010;23(2):247-69. doi: 10.1017/S0954422410000144
B35: IMLG | C35: =C34/(C9*C9) -> #NUM! | J35: Cintura: Res 2465 de 2016 Ministerio de salud y proteccion social
B36: Clasificación | C36: =IF(C6="Hombre",IF(C35<17,"Malnutricion",IF(AND(C35>=17,C35<=21),"Adecuado","Muy buena")),IF(C35<15,"Malnutricion",IF(AND(C35>=15,C35<=18),"Adecuado","Muy buena"))) -> #NUM! | F36: En caso Malnutrición | J36: %Grasa: Davidson LE, Wang J, Thornton JC, Kaleem Z, Silva-Palacios F, Person RN, et al. Predicting fat percent by skinfolds in racial groups: Durnin and Womersley revisited. Medicine and science in sports and exercise. 2011; 43(3): 542-9
B37: %Grasa deseado | F37: %Grasa deseado | J37: Clasificación %Grasa: Consenso SEEDO 2000 para la evaluacion del sobrepeso y la obesidad y el establecimiento de criterios de intervencion terapeutica. Medicina clinica. 115 (15).
B38: Peso deseado %G kg | C38: =IF(C36="Malnutrición","Malnutrición",C34/(1-(C37/100))) -> #NUM! | F38: IMLG kg deseado | J38: Clasificación IMG: Kelly TL, Wilson KE, Heymsfield SB. Dual energy X-Ray absorptiometry body composition reference values from NHANES. PLoS One. 2009 Sep 15;4(9):e7038. doi: 10.1371/journal.pone.0007038.
B39: Distribucion Grasa | C39: =(C15+C16)/(C17+C14) -> #DIV/0! | E39: =(C15+C16)/(C17+C14) -> #DIV/0! | F39: MLG kg Adecuada | G39: =IF(C36="Malnutricion",G38*(C9*C9),"No aplica") -> #NUM! | J39: Clasificación IMLG: Cederholm, T., Jensen, G. L., Correia, M. I. T. D., Gonzalez, M. C., Fukushima, R., Higashiguchi, T., … Coats, A. (2018). GLIM criteria for the diagnosis of malnutrition – A consensus report from the global clinical nutrition community. Clinical Nutrition. doi:10.1016/j.clnu.2018.08.002
B40: Clasificación | C40: =IF(C39<1,"Acumulacion periferica",IF(C39=1,"Distribucion armonica","Acumulacion central")) -> #DIV/0! | F40: Peso deseado %G Kg | G40: =IF(C36="Malnutricion",G39/(1-(G37/100)),"No aplica") -> #NUM! | J40: Distribución de la grasa: Malina, R.M. (1996) Regional body composition: Age, sex and ethnic variation. In: Roche, A.F., Heymsfield, S.B. and Lohman, T.G., Eds., Human Body Composition, Human Kinetics, Champaign, 217-256.

Sheet Hoja1

Sheet Ev. Consumo
D3: EVALUACIÓN DE CONSUMO
B5: Tamaño de porción Aprox | D5: Grupo de alimentos | J5: Porciones | K5: Kcal | L5: Prot | M5: Grasa | N5: GS | O5: GM | P5: GP | Q5: COL | R5: CHOS | S5: FD | T5: Calcio (mg) | U5: P (mg) | V5: Fe (mg) | W5: Na (mg) | X5: K (mg) | Y5: Mg (mg) | Z5: Zn (mg) | AA5: Cu (mg) | AB5: Mn (mg) | AC5: Vit A (ER) | AD5: Tiamina (mg) | AE5: Riboflavina (mg) | AF5: Niacina (mg) | AG5: Ac, Pantotenico (mg) | AH5: Priridox. (mg) | AI5: Acido Folico (ug) | AJ5: Vit B12 (ug) | AK5: Vit C (mg)
B6: 200g | C6: 1 Vaso pequeño | D6: Leches enteras frescas y fermentadas | K6: =(L6*4)+(M6*9)+(R6*4) -> 139.1 | L6: 6.7 | M6: 6.7 | N6: 4.4 | O6: 1.95 | P6: 0.49 | Q6: 26 | R6: 13 | S6: 0 | T6: 236 | U6: 173 | V6: 0.2 | W6: 96 | X6: 330 | Y6: 25 | Z6: 0.89 | AA6: 0.03 | AB6: 0.01 | AC6: 73 | AD6: 0.08 | AE6: 0.34 | AF6: 0.3 | AG6: 0.67 | AH6: 0.08 | AI6: 10 | AJ6: 0.65 | AK6: 3
B7: 200g | C7: 1 Vaso pequeño | D7: Leches semidescremadas frescas y fermentadas | K7: =(L7*4)+(M7*9)+(R7*4) -> 94.5 | L7: 5.4 | M7: 2.1 | N7: 0.87 | O7: 0.54 | P7: 0.35 | Q7: 5 | R7: 13.5 | S7: 0.8 | T7: 153 | U7: 143 | V7: 0.4 | W7: 72 | X7: 268 | Y7: 25 | Z7: 1.24 | AA7: 0.06 | AB7: 0.11 | AC7: 76 | AD7: 0.12 | AE7: 0.25 | AF7: 0.2 | AG7: 0.41 | AH7: 0.06 | AI7: 8 | AJ7: 0.5 | AK7: 4
B8: 200g | C8: 1 Vaso pequeño | D8: Leches descremadas frescas y fermentadas | K8: =(L8*4)+(M8*9)+(R8*4) -> 82.3 | L8: 9 | M8: 0.7 | N8: 0.45 | O8: 0.18 | P8: 0.03 | Q8: 6 | R8: 10 | S8: 0 | T8: 256 | U8: 214 | V8: 0.1 | W8: 101 | X8: 340 | Y8: 24 | Z8: 1.05 | AA8: 0.02 | AB8: 0.01 | AC8: 89 | AD8: 0.08 | AE8: 0.33 | AF8: 0.2 | AG8: 0.79 | AH8: 0.08 | AI8: 14 | AJ8: 0.84 | AK8: 2
B9: 200g | C9: 1 Vaso pequeño | D9: Leches frescas y fermentadas enteras altas en calorías y azucares | K9: =(L9*4)+(M9*9)+(R9*4) -> 170.7 | L9: 6.4 | M9: 5.9 | N9: 3.8 | O9: 1.91 | P9: 0.63 | Q9: 22 | R9: 23 | S9: 0.4 | T9: 258 | U9: 169 | V9: 0.3 | W9: 115 | X9: 334 | Y9: 27 | Z9: 1.03 | AA9: 0.05 | AB9: 0.04 | AC9: 45 | AD9: 0.08 | AE9: 0.37 | AF9: 0.2 | AG9: 0.73 | AH9: 0.08 | AI9: 13 | AJ9: 0.76 | AK9: 3
B10: 60g | C10: 1/3 Vaso pequeño | D10: Leches frescas, fermentadas y productos lácteos menores de 2 años | K10: =(L10*4)+(M10*9)+(R10*4) -> 50.7 | L10: 2.9 | M10: 3.1 | N10: 2.01 | O10: 0.96 | P10: 0.18 | Q10: 12 | R10: 2.8 | S10: 0 | T10: 93 | U10: 62 | V10: 0.1 | W10: 57 | X10: 57 | Y10: 6 | Z10: 0.38 | AA10: 0.01 | AB10: 0 | AC10: 36 | AD10: 0.01 | AE10: 0.08 | AF10: 0.1 | AG10: 0.12 | AH10: 0.02 | AI10: 2 | AJ10: 0.2 | AK10: 0
B11: 100ml | C11: 1 toma | D11: Leche materna | K11: =(L11*4)+(M11*9)+(R11*4) -> 71.2 | L11: 1 | M11: 4.4 | N11: 2.01 | O11: 1.66 | P11: 0.5 | Q11: 14 | R11: 6.9 | S11: 0 | T11: 32 | U11: 14 | V11: 0 | W11: 17 | X11: 51 | Y11: 3 | Z11: 0.17 | AA11: 0.05 | AB11: 0.03 | AC11: 64 | AD11: 0.01 | AE11: 0.04 | AF11: 0.2 | AG11: 0.22 | AH11: 0.01 | AI11: 5 | AJ11: 0.05 | AK11: 5
B12: 30g | C12: 1 tajada/1 unidad mediana | D12: Sustitutos | K12: =(L12*4)+(M12*9)+(R12*4) -> 77.1 | L12: 5.8 | M12: 5.5 | N12: 2.91 | O12: 1.94 | P12: 0.41 | Q12: 40 | R12: 1.1 | S12: 0 | T12: 95 | U12: 85 | V12: 1.1 | W12: 211 | X12: 52 | Y12: 6 | Z12: 0.65 | AA12: 0.03 | AB12: 0.01 | AC12: 45 | AD12: 0.04 | AE12: 0.1 | AF12: 0.4 | AG12: 0.16 | AH12: 0.05 | AI12: 4 | AJ12: 0.72 | AK12: 0
B13: 30g | C13: 1 unidad | D13: Huevo menores de 2 años | K13: =(L13*4)+(M13*9)+(R13*4) -> 52.9 | L13: 4.5 | M13: 3.7 | N13: 1.15 | O13: 1.42 | P13: 0.49 | Q13: 180 | R13: 0.4 | S13: 0 | T13: 19 | U13: 64 | V13: 0.6 | W13: 46 | X13: 46 | Y13: 4 | Z13: 0.4 | AA13: 0.01 | AB13: 0.01 | AC13: 57 | AD13: 0.03 | AE13: 0.2 | AF13: 0 | AG13: 0.51 | AH13: 0.05 | AI13: 18 | AJ13: 0.43 | AK13: 0
B14: 100g | C14: 1/5 libra | D14: Carnes magras crudas y proteínas texturizada adultos y niños | K14: =(L14*4)+(M14*9)+(R14*4) -> 108.3 | L14: 19.1 | M14: 3.1 | N14: 0.92 | O14: 1.16 | P14: 0.53 | Q14: 50 | R14: 1 | S14: 0.3 | T14: 22 | U14: 191 | V14: 1.5 | W14: 72 | X14: 325 | Y14: 28 | Z14: 1.81 | AA14: 0.11 | AB14: 0.12 | AC14: 7 | AD14: 0.19 | AE14: 0.18 | AF14: 5.6 | AG14: 0.78 | AH14: 0.35 | AI14: 15 | AJ14: 2.39 | AK14: 1
B15: 25g | C15: 3 cucharas dulceras colmadas | D15: Carnes magras cocidas menores de 2 años | K15: =(L15*4)+(M15*9)+(R15*4) -> 49.2 | L15: 7.8 | M15: 2 | N15: 0.52 | O15: 0.84 | P15: 0.35 | Q15: 21 | R15: 0 | S15: 0 | T15: 7 | U15: 74 | V15: 0.4 | W15: 19 | X15: 108 | Y15: 8 | Z15: 0.55 | AA15: 0.04 | AB15: 0.09 | AC15: 5 | AD15: 0.1 | AE15: 0.07 | AF15: 1.9 | AG15: 0.33 | AH15: 0.09 | AI15: 2 | AJ15: 1 | AK15: 0
B16: 90g | C16: < 1/5 libra | D16: Carnes crudas altas en lípidos adultos y niños | K16: =(L16*4)+(M16*9)+(R16*4) -> 138.7 | L16: 15.6 | M16: 7.9 | N16: 2.51 | O16: 3.3 | P16: 1.25 | Q16: 137 | R16: 1.3 | S16: 0 | T16: 37 | U16: 186 | V16: 2.5 | W16: 101 | X16: 234 | Y16: 20 | Z16: 1.87 | AA16: 0.47 | AB16: 0.09 | AC16: 1515 | AD16: 0.07 | AE16: 0.53 | AF16: 4.4 | AG16: 1.67 | AH16: 0.27 | AI16: 87 | AJ16: 10.58 | AK16: 6
B17: 25g | C17: 3 cucharas dulceras colmadas | D17: Carnes cocidas altas en lípidos menores de 2 años | K17: =(L17*4)+(M17*9)+(R17*4) -> 46.8 | L17: 6.9 | M17: 2 | N17: 0.78 | O17: 0.86 | P17: 0.31 | Q17: 79 | R17: 0.3 | S17: 0 | T17: 3 | U17: 57 | V17: 3 | W17: 62 | X17: 55 | Y17: 6 | Z17: 1.21 | AA17: 0.25 | AB17: 0.04 | AC17: 620 | AD17: 0.02 | AE17: 0.29 | AF17: 1.1 | AG17: 0.55 | AH17: 0.09 | AI17: 39 | AJ17: 4.29 | AK17: 2
... B46: 3g | C46: 1 cuchara dulcera | D46: Promedio grasas menores de 2 años | K46: =(L46*4)+(M46*9)+(R46*4) -> 26.8 | L46: 0.2 | M46: 2.8 | N46: 0.81 | O46: 1.12 | P46: 0.76 | Q46: 2 | R46: 0.2 | S46: 0.1 | T46: 2 | U46: 3 | V46: 0 | W46: 3 | X46: 15 | Y46: 1 | Z46: 0.02 | AA46: 0.01 | AB46: 0.01 | AC46: 9 | AD46: 0 | AE46: 0.01 | AF46: 0.1 | AG46: 0.03 | AH46: 0.01 | AI46: 2 | AJ46: 0.01 | AK46: 0
B47: 1u | C47: 1 porción | D47: Suplemento (Introduzca manualmente los nutrientes por porción)
D50: Grupo de alimentos | J50: Porciones | K50: Kcal | L50: Prot | M50: Grasa | N50: GS | O50: GM | P50: GP | Q50: COL | R50: CHOS | S50: FD | T50: Calcio (mg) | U50: P (mg) | V50: Fe (mg) | W50: Na (mg) | X50: K (mg) | Y50: Mg (mg) | Z50: Zn (mg) | AA50: Cu (mg) | AB50: Mn (mg) | AC50: Vit A (ER) | AD50: Tiamina (mg) | AE50: Riboflavina (mg) | AF50: Niacina (mg) | AG50: Ac, Pantotenico (mg) | AH50: Priridox. (mg) | AI50: Acido Folico (ug) | AJ50: Vit B12 (ug) | AK50: Vit C (mg)
D51: Leches enteras frescas y fermentadas | J51: =J6 | K51: =(K6*J6) -> 0 | L51: =(L6*J6) -> 0 | M51: =(M6*J6) -> 0 | N51: =(N6*J6) -> 0 | O51: =(O6*J6) -> 0 | P51: =(P6*J6) -> 0 | Q51: =(Q6*J6) -> 0 | R51: =(R6*J6) -> 0 | S51: =(S6*J6) -> 0 | T51: =(T6*J6) -> 0 | U51: =(U6*J6) -> 0 | V51: =(V6*J6) -> 0 | W51: =(W6*J6) -> 0 | X51: =(X6*J6) -> 0 | Y51: =(Y6*J6) -> 0 | Z51: =(Z6*J6) -> 0 | AA51: =(AA6*J6) -> 0 | AB51: =(AB6*J6) -> 0 | AC51: =(AC6*J6) -> 0 | AD51: =(AD6*J6) -> 0 | AE51: =(AE6*J6) -> 0 | AF51: =(AF6*J6) -> 0 | AG51: =(AG6*J6) -> 0 | AH51: =(AH6*J6) -> 0 | AI51: =(AI6*J6) -> 0 | AJ51: =(AJ6*J6) -> 0 | AK51: =(AK6*J6) -> 0
D52: Leches semidescremadas frescas y fermentadas | J52: =J7 | K52: =(K7*J7) -> 0 | L52: =(L7*J7) -> 0 | M52: =(M7*J7) -> 0 | N52: =(N7*J7) -> 0 | O52: =(O7*J7) -> 0 | P52: =(P7*J7) -> 0 | Q52: =(Q7*J7) -> 0 | R52: =(R7*J7) -> 0 | S52: =(S7*J7) -> 0 | T52: =(T7*J7) -> 0 | U52: =(U7*J7) -> 0 | V52: =(V7*J7) -> 0 | W52: =(W7*J7) -> 0 | X52: =(X7*J7) -> 0 | Y52: =(Y7*J7) -> 0 | Z52: =(Z7*J7) -> 0 | AA52: =(AA7*J7) -> 0 | AB52: =(AB7*J7) -> 0 | AC52: =(AC7*J7) -> 0 | AD52: =(AD7*J7) -> 0 | AE52: =(AE7*J7) -> 0 | AF52: =(AF7*J7) -> 0 | AG52: =(AG7*J7) -> 0 | AH52: =(AH7*J7) -> 0 | AI52: =(AI7*J7) -> 0 | AJ52: =(AJ7*J7) -> 0 | AK52: =(AK7*J7) -> 0
D53: Leches descremadas frescas y fermentadas | J53: =J8 | K53: =(K8*J8) -> 0 | L53: =(L8*J8) -> 0 | M53: =(M8*J8) -> 0 | N53: =(N8*J8) -> 0 | O53: =(O8*J8) -> 0 | P53: =(P8*J8) -> 0 | Q53: =(Q8*J8) -> 0 | R53: =(R8*J8) -> 0 | S53: =(S8*J8) -> 0 | T53: =(T8*J8) -> 0 | U53: =(U8*J8) -> 0 | V53: =(V8*J8) -> 0 | W53: =(W8*J8) -> 0 | X53: =(X8*J8) -> 0 | Y53: =(Y8*J8) -> 0 | Z53: =(Z8*J8) -> 0 | AA53: =(AA8*J8) -> 0 | AB53: =(AB8*J8) -> 0 | AC53: =(AC8*J8) -> 0 | AD53: =(AD8*J8) -> 0 | AE53: =(AE8*J8) -> 0 | AF53: =(AF8*J8) -> 0 | AG53: =(AG8*J8) -> 0 | AH53: =(AH8*J8) -> 0 | AI53: =(AI8*J8) -> 0 | AJ53: =(AJ8*J8) -> 0 | AK53: =(AK8*J8) -> 0
D54: Leches frescas y fermentadas enteras altas en calorías y azucares | J54: =J9 | K54: =(K9*J9) -> 0 | L54: =(L9*J9) -> 0 | M54: =(M9*J9) -> 0 | N54: =(N9*J9) -> 0 | O54: =(O9*J9) -> 0 | P54: =(P9*J9) -> 0 | Q54: =(Q9*J9) -> 0 | R54: =(R9*J9) -> 0 | S54: =(S9*J9) -> 0 | T54: =(T9*J9) -> 0 | U54: =(U9*J9) -> 0 | V54: =(V9*J9) -> 0 | W54: =(W9*J9) -> 0 | X54: =(X9*J9) -> 0 | Y54: =(Y9*J9) -> 0 | Z54: =(Z9*J9) -> 0 | AA54: =(AA9*J9) -> 0 | AB54: =(AB9*J9) -> 0 | AC54: =(AC9*J9) -> 0 | AD54: =(AD9*J9) -> 0 | AE54: =(AE9*J9) -> 0 | AF54: =(AF9*J9) -> 0 | AG54: =(AG9*J9) -> 0 | AH54: =(AH9*J9) -> 0 | AI54: =(AI9*J9) -> 0 | AJ54: =(AJ9*J9) -> 0 | AK54: =(AK9*J9) -> 0
D55: Leches frescas, fermentadas y productos lácteos menores de 2 años | J55: =J10 | K55: =(K10*J10) -> 0 | L55: =(L10*J10) -> 0 | M55: =(M10*J10) -> 0 | N55: =(N10*J10) -> 0 | O55: =(O10*J10) -> 0 | P55: =(P10*J10) -> 0 | Q55: =(Q10*J10) -> 0 | R55: =(R10*J10) -> 0 | S55: =(S10*J10) -> 0 | T55: =(T10*J10) -> 0 | U55: =(U10*J10) -> 0 | V55: =(V10*J10) -> 0 | W55: =(W10*J10) -> 0 | X55: =(X10*J10) -> 0 | Y55: =(Y10*J10) -> 0 | Z55: =(Z10*J10) -> 0 | AA55: =(AA10*J10) -> 0 | AB55: =(AB10*J10) -> 0 | AC55: =(AC10*J10) -> 0 | AD55: =(AD10*J10) -> 0 | AE55: =(AE10*J10) -> 0 | AF55: =(AF10*J10) -> 0 | AG55: =(AG10*J10) -> 0 | AH55: =(AH10*J10) -> 0 | AI55: =(AI10*J10) -> 0 | AJ55: =(AJ10*J10) -> 0 | AK55: =(AK10*J10) -> 0
D56: Leche materna | J56: =J11 | K56: =(K11*J11) -> 0 | L56: =(L11*J11) -> 0 | M56: =(M11*J11) -> 0 | N56: =(N11*J11) -> 0 | O56: =(O11*J11) -> 0 | P56: =(P11*J11) -> 0 | Q56: =(Q11*J11) -> 0 | R56: =(R11*J11) -> 0 | S56: =(S11*J11) -> 0 | T56: =(T11*J11) -> 0 | U56: =(U11*J11) -> 0 | V56: =(V11*J11) -> 0 | W56: =(W11*J11) -> 0 | X56: =(X11*J11) -> 0 | Y56: =(Y11*J11) -> 0 | Z56: =(Z11*J11) -> 0 | AA56: =(AA11*J11) -> 0 | AB56: =(AB11*J11) -> 0 | AC56: =(AC11*J11) -> 0 | AD56: =(AD11*J11) -> 0 | AE56: =(AE11*J11) -> 0 | AF56: =(AF11*J11) -> 0 | AG56: =(AG11*J11) -> 0 | AH56: =(AH11*J11) -> 0 | AI56: =(AI11*J11) -> 0 | AJ56: =(AJ11*J11) -> 0 | AK56: =(AK11*J11) -> 0
D57: Sustitutos | J57: =J12 | K57: =(K12*J12) -> 0 | L57: =(L12*J12) -> 0 | M57: =(M12*J12) -> 0 | N57: =(N12*J12) -> 0 | O57: =(O12*J12) -> 0 | P57: =(P12*J12) -> 0 | Q57: =(Q12*J12) -> 0 | R57: =(R12*J12) -> 0 | S57: =(S12*J12) -> 0 | T57: =(T12*J12) -> 0 | U57: =(U12*J12) -> 0 | V57: =(V12*J12) -> 0 | W57: =(W12*J12) -> 0 | X57: =(X12*J12) -> 0 | Y57: =(Y12*J12) -> 0 | Z57: =(Z12*J12) -> 0 | AA57: =(AA12*J12) -> 0 | AB57: =(AB12*J12) -> 0 | AC57: =(AC12*J12) -> 0 | AD57: =(AD12*J12) -> 0 | AE57: =(AE12*J12) -> 0 | AF57: =(AF12*J12) -> 0 | AG57: =(AG12*J12) -> 0 | AH57: =(AH12*J12) -> 0 | AI57: =(AI12*J12) -> 0 | AJ57: =(AJ12*J12) -> 0 | AK57: =(AK12*J12) -> 0
D58: Huevo menores de 2 años | J58: =J13 | K58: =(K13*J13) -> 0 | L58: =(L13*J13) -> 0 | M58: =(M13*J13) -> 0 | N58: =(N13*J13) -> 0 | O58: =(O13*J13) -> 0 | P58: =(P13*J13) -> 0 | Q58: =(Q13*J13) -> 0 | R58: =(R13*J13) -> 0 | S58: =(S13*J13) -> 0 | T58: =(T13*J13) -> 0 | U58: =(U13*J13) -> 0 | V58: =(V13*J13) -> 0 | W58: =(W13*J13) -> 0 | X58: =(X13*J13) -> 0 | Y58: =(Y13*J13) -> 0 | Z58: =(Z13*J13) -> 0 | AA58: =(AA13*J13) -> 0 | AB58: =(AB13*J13) -> 0 | AC58: =(AC13*J13) -> 0 | AD58: =(AD13*J13) -> 0 | AE58: =(AE13*J13) -> 0 | AF58: =(AF13*J13) -> 0 | AG58: =(AG13*J13) -> 0 | AH58: =(AH13*J13) -> 0 | AI58: =(AI13*J13) -> 0 | AJ58: =(AJ13*J13) -> 0 | AK58: =(AK13*J13) -> 0
D59: Carnes magras crudas y proteínas texturizada adultos y niños | J59: =J14 | K59: =(K14*J14) -> 0 | L59: =(L14*J14) -> 0 | M59: =(M14*J14) -> 0 | N59: =(N14*J14) -> 0 | O59: =(O14*J14) -> 0 | P59: =(P14*J14) -> 0 | Q59: =(Q14*J14) -> 0 | R59: =(R14*J14) -> 0 | S59: =(S14*J14) -> 0 | T59: =(T14*J14) -> 0 | U59: =(U14*J14) -> 0 | V59: =(V14*J14) -> 0 | W59: =(W14*J14) -> 0 | X59: =(X14*J14) -> 0 | Y59: =(Y14*J14) -> 0 | Z59: =(Z14*J14) -> 0 | AA59: =(AA14*J14) -> 0 | AB59: =(AB14*J14) -> 0 | AC59: =(AC14*J14) -> 0 | AD59: =(AD14*J14) -> 0 | AE59: =(AE14*J14) -> 0 | AF59: =(AF14*J14) -> 0 | AG59: =(AG14*J14) -> 0 | AH59: =(AH14*J14) -> 0 | AI59: =(AI14*J14) -> 0 | AJ59: =(AJ14*J14) -> 0 | AK59: =(AK14*J14) -> 0
D60: Carnes magras cocidas menores de 2 años | J60: =J15 | K60: =(K15*J15) -> 0 | L60: =(L15*J15) -> 0 | M60: =(M15*J15) -> 0 | N60: =(N15*J15) -> 0 | O60: =(O15*J15) -> 0 | P60: =(P15*J15) -> 0 | Q60: =(Q15*J15) -> 0 | R60: =(R15*J15) -> 0 | S60: =(S15*J15) -> 0 | T60: =(T15*J15) -> 0 | U60: =(U15*J15) -> 0 | V60: =(V15*J15) -> 0 | W60: =(W15*J15) -> 0 | X60: =(X15*J15) -> 0 | Y60: =(Y15*J15) -> 0 | Z60: =(Z15*J15) -> 0 | AA60: =(AA15*J15) -> 0 | AB60: =(AB15*J15) -> 0 | AC60: =(AC15*J15) -> 0 | AD60: =(AD15*J15) -> 0 | AE60: =(AE15*J15) -> 0 | AF60: =(AF15*J15) -> 0 | AG60: =(AG15*J15) -> 0 | AH60: =(AH15*J15) -> 0 | AI60: =(AI15*J15) -> 0 | AJ60: =(AJ15*J15) -> 0 | AK60: =(AK15*J15) -> 0
D61: Carnes crudas altas en lípidos adultos y niños | J61: =J16 | K61: =(K16*J16) -> 0 | L61: =(L16*J16) -> 0 | M61: =(M16*J16) -> 0 | N61: =(N16*J16) -> 0 | O61: =(O16*J16) -> 0 | P61: =(P16*J16) -> 0 | Q61: =(Q16*J16) -> 0 | R61: =(R16*J16) -> 0 | S61: =(S16*J16) -> 0 | T61: =(T16*J16) -> 0 | U61: =(U16*J16) -> 0 | V61: =(V16*J16) -> 0 | W61: =(W16*J16) -> 0 | X61: =(X16*J16) -> 0 | Y61: =(Y16*J16) -> 0 | Z61: =(Z16*J16) -> 0 | AA61: =(AA16*J16) -> 0 | AB61: =(AB16*J16) -> 0 | AC61: =(AC16*J16) -> 0 | AD61: =(AD16*J16) -> 0 | AE61: =(AE16*J16) -> 0 | AF61: =(AF16*J16) -> 0 | AG61: =(AG16*J16) -> 0 | AH61: =(AH16*J16) -> 0 | AI61: =(AI16*J16) -> 0 | AJ61: =(AJ16*J16) -> 0 | AK61: =(AK16*J16) -> 0
D62: Carnes cocidas altas en lípidos menores de 2 años | J62: =J17 | K62: =(K17*J17) -> 0 | L62: =(L17*J17) -> 0 | M62: =(M17*J17) -> 0 | N62: =(N17*J17) -> 0 | O62: =(O17*J17) -> 0 | P62: =(P17*J17) -> 0 | Q62: =(Q17*J17) -> 0 | R62: =(R17*J17) -> 0 | S62: =(S17*J17) -> 0 | T62: =(T17*J17) -> 0 | U62: =(U17*J17) -> 0 | V62: =(V17*J17) -> 0 | W62: =(W17*J17) -> 0 | X62: =(X17*J17) -> 0 | Y62: =(Y17*J17) -> 0 | Z62: =(Z17*J17) -> 0 | AA62: =(AA17*J17) -> 0 | AB62: =(AB17*J17) -> 0 | AC62: =(AC17*J17) -> 0 | AD62: =(AD17*J17) -> 0 | AE62: =(AE17*J17) -> 0 | AF62: =(AF17*J17) -> 0 | AG62: =(AG17*J17) -> 0 | AH62: =(AH17*J17) -> 0 | AI62: =(AI17*J17) -> 0 | AJ62: =(AJ17*J17) -> 0 | AK62: =(AK17*J17) -> 0
... D92: suplemento | J92: =J47 | K92: =(K47*J47) -> 0 | L92: =(L47*J47) -> 0 | M92: =(M47*J47) -> 0 | N92: =(N47*J47) -> 0 | O92: =(O47*J47) -> 0 | P92: =(P47*J47) -> 0 | Q92: =(Q47*J47) -> 0 | R92: =(R47*J47) -> 0 | S92: =(S47*J47) -> 0 | T92: =(T47*J47) -> 0 | U92: =(U47*J47) -> 0 | V92: =(V47*J47) -> 0 | W92: =(W47*J47) -> 0 | X92: =(X47*J47) -> 0 | Y92: =(Y47*J47) -> 0 | Z92: =(Z47*J47) -> 0 | AA92: =(AA47*J47) -> 0 | AB92: =(AB47*J47) -> 0 | AC92: =(AC47*J47) -> 0 | AD92: =(AD47*J47) -> 0 | AE92: =(AE47*J47) -> 0 | AF92: =(AF47*J47) -> 0 | AG92: =(AG47*J47) -> 0 | AH92: =(AH47*J47) -> 0 | AI92: =(AI47*J47) -> 0 | AJ92: =(AJ47*J47) -> 0 | AK92: =(AK47*J47) -> 0
B93: TOTAL | K93: =SUM(K51:K92) -> 0 | L93: =SUM(L51:L92) -> 0 | M93: =SUM(M51:M92) -> 0 | N93: =SUM(N51:N92) -> 0 | O93: =SUM(O51:O92) -> 0 | P93: =SUM(P51:P92) -> 0 | Q93: =SUM(Q51:Q92) -> 0 | R93: =SUM(R51:R92) -> 0 | ... AK93: =SUM(AK51:AK92) -> 0
J94: REQUERIDO | K94: =D1 | L94: =E1 | M94: =F1 | N94: =G1 | O94: =H1 | P94: =I1 | Q94: =J1 | R94: =K1 | S94: =L1
J95: %ADECUACI | K95: =((100/K94)*K93) -> #DIV/0! | L95: =((100/L94)*L93) -> #DIV/0! | M95: =((100/M94)*M93) -> #DIV/0! | N95: =((100/N94)*N93) -> #DIV/0! | O95: =((100/O94)*O93) -> #DIV/0! | P95: =((100/P94)*P93) -> #DIV/0! | Q95: =((100/Q94)*Q93) -> #DIV/0! | R95: =((100/R94)*R93) -> #DIV/0! | ... AK95: =((100/AK94)*AK93) -> #DIV/0!
K96: Kcal | L96: Prot | M96: Grasa | N96: GS | O96: GM | P96: GP | Q96: COL | R96: CHOS | S96: FD | T96: Calcio (mg) | U96: P (mg) | V96: Fe (mg) | W96: Na (mg) | X96: K (mg) | Y96: Mg (mg) | Z96: Zn (mg) | AA96: Cu (mg) | AB96: Mn (mg) | AC96: Vit A (ER) | AD96: Tiamina (mg) | AE96: Riboflavina (mg) | AF96: Niacina (mg) | AG96: Ac, Pantotenico (mg) | AH96: Priridox. (mg) | AI96: Acido Folico (ug) | AJ96: Vit B12 (ug) | AK96: Vit C (mg)
D98: FÓRMULA SINTÉTICA DE CONSUMO
K100: FÓRMULA SINTÉTICA DE CONSUMO | Q100: Recomendaciones RIEN
K101: Nutrientes | L101: Gramos | M101: Calorías | N101: % AMDR | O101: Otros | Q101: Proteinas | S101: 14-20%
K102: Proteínas | L102: =(L93) -> 0 | M102: =(L102*4) -> 0 | N102: =((100/M114)*M102) -> #DIV/0! | O102: g AVB | P102: =SUM(L51:L62) -> 0 | Q102: Prote g/kg/peso | S102: 1,11-1,16
O103: % AVB | P103: =((100/L102)*P102) -> #DIV/0! | Q103: Prote AVB | S103: 60-80%
O104: g/kg/peso | P104: =(L102/L115) -> #DIV/0! | Q104: Carbohidratos totales | S104: 50-65%
...

Sheet Adulto
B3: REQUERIMIENTO ENERGÉTICO Y PESO SALUDABLE
B5: PESO SALUDABLE IMC | E5: TMR FAO/Schofield | H5: ACTIVIDAD FISICA | L5: REQUERIMIENTO DRI | O5: FACTOR ACTIVIDAD FISICA PAL
B6: Peso kg | C6: 63 | E6: Peso Ref | F6: 75 | H6: Sedentario | I6: 1.53 | J6: (1,4-1,69) | L6: Edad | P6: Hombres | Q6: Mujeres
B7: Talla m | C7: 1.73 | E7: TMR HOMBRES | H7: Moderado | I7: 1.76 | J7: (1,7-1,99) | L7: Peso kg | O7: Sedentario | P7: 1 | Q7: 1
B8: IMC | C8: =(C6/(C7*C7)) -> 21.049818 | E8: 18-30 años | F8: =((15.057*F6)+692.2) -> 1821.475 | H8: Vigoroso | I8: 2.25 | J8: (2,0-2,4) | L8: Talla m | O8: Poco activo | P8: 1.11 | Q8: 1.12
B9: IMC deseado | C9: 25 | E9: 31-60 años | F9: =((11.472*F6)+873.1) -> 1733.5 | L9: Factor act | O9: Activo | P9: 1.25 | Q9: 1.27
B10: Peso saludable IMC 25-30 | E10: >60 años | F10: =((11.711*F6)+587.7) -> 1466.025 | H10: REQUERIMIENTO | L10: HOMBRES | O10: Muy activo | P10: 1.48 | Q10: 1.45
B11: PS | C11: =(C9*(C7*C7)) -> 74.8225 | E11: TMR MUJERES | H11: TMR | I11: 1821 | L11: RDE | M11: =662-(9.53*M6)+(M9*((15.91*M7)+(539.6*M8))) -> 662
B12: Peso ajustado IMC >30 | E12: 18-30 años | F12: =((14.818*F6)+486.6) -> 1597.95 | H12: ACT FIS | I12: 1.5 | L12: MUJERES
B13: PA | C13: =(C11+(0.25*(C6-C11))) -> 71.866875 | E13: 31-60 años | F13: =((8.126*F6)+845.6) -> 1455.05 | H13: Calorias | I13: =(I11*I12) -> 2731.5 | L13: RDE | M13: =354-(6.91*M6)+(M9*((9.36*M7)+(726*M8))) -> 354
E14: >60 años | F14: =((9.082*F6)+658.5) -> 1339.65
B16: FÓRMULA SINTÉTICA DE CONSUMO Y PLANEADA
B18: FÓRMULA SINTÉTICA DE CONSUMO | I18: FÓRMULA SINTÉTICA PLANEADA | P18: Recomendaciones RIEN
B19: Nutrientes | C19: Gramos | D19: Calorias | E19: % AMDR | F19: Otros | I19: Nutrientes | J19: Gramos | K19: Calorías | L19: % AMDR | M19: Otros | P19: Proteínas | R19: 14-20% AMDR
B20: Proteínas | C20: ='Ev. Consumo'!L102 -> 0 | D20: =(C20*4) -> 0 | E20: =((100/D32)*D20) -> #DIV/0! | F20: g AVB | G20: ='Ev. Consumo'!P102 -> 0 | I20: Proteínas | J20: =(N22*J33) -> 127.5 | K20: =(J20*4) -> 510 | L20: =((100/K32)*K20) -> 18.67106 | M20: g AVB | N20: =((N21/100)*J20) -> 89.25 | P20: Prote g/kg/peso | R20: 1,11-1,16
F21: % AVB | G21: =((100/C20)*G20) -> #DIV/0! | M21: % AVB | N21: 70 | P21: Prote AVB | R21: 60-80%
F22: g/kg/peso | G22: =(C20/C33) -> #DIV/0! | M22: g/kg/peso | N22: 1.7 | P22: CHOs totales | R22: 50-65%
B23: Grasas | C23: ='Ev. Consumo'!L105 -> 0 | D23: =(C23*9) -> 0 | E23: =((100/D32)*D23) -> #DIV/0! | F23: g GS | G23: ='Ev. Consumo'!P105 -> 0 | I23: Grasas | J23: =(K23/9) -> 75.875 | K23: =((K32/100)*L23) -> 682.875 | L23: 25 | M23: g GS | N23: =(((K32/100)*N24)/9) -> 30.35 | P23: CHOs simples | R23: <10%
F24: %AMDR GS | G24: =((100/D32)*(G23*9)) -> #DIV/0! | M24: %AMDR GS | N24: 10 | P24: Grasa total 27,5 | R24: 20-35% AMDR
F25: g GM | G25: ='Ev. Consumo'!P107 -> 0 | M25: g GM | N25: =(((K32/100)*N26)/9) -> 15.175 | P25: G saturada | R25: <10%
F26: %AMDR GM | G26: =((100/D32)*(G25*9)) -> #DIV/0! | M26: %AMDR GM | N26: =(L23-N24)-N28 -> 5 | P26: G poli | R26: 5-10%
F27: g GP | G27: ='Ev. Consumo'!P109 -> 0 | M27: g GP | N27: =(((K32/100)*N28)/9) -> 30.35 | P27: G mono | R27: GS-GM
F28: %AMDR GP | G28: =((100/D32)*(G27*9)) -> #DIV/0! | M28: %AMDR GP | N28: 10 | P28: G trans | R28: <1%
F29: Colesterol | G29: ='Ev. Consumo'!P111 -> 0 | M29: Colesterol | N29: 200 | P29: Colesterol | R29: <300mg
B30: CHOs | C30: ='Ev. Consumo'!L112 -> 0 | D30: =(C30*4) -> 0 | E30: =((100/D32)*D30) -> #DIV/0! | F30: g Concent | G30: ='Ev. Consumo'!P112 -> 0 | I30: CHOs | J30: =(K30/4) -> 384.65625 | K30: =((K32/100)*L30) -> 1538.625 | L30: =(100-L33) -> 56.32894 | M30: g Concent | N30: =(((K32/100)*N31)/4) -> 184.37625 | P30: Colesterol enf.card | R30: <200mg
F31: %AMDR | G31: =((100/D32)*(G30*4)) -> #DIV/0! | M31: %AMDR | N31: 27 | P31: Fibra | R31: 14g/1000cal
B32: Total: | D32: =SUM(D20:D31) -> 0 | E32: =SUM(E20:E31) -> #DIV/0! | F32: Fibra | G32: ='Ev. Consumo'!P114 -> 0 | I32: Total: | K32: =I13 -> 2731.5 | L32: =SUM(L20:L31) -> 100 | M32: Fibra | N32: 14 | P32: Sodio | R32: <2300mg
B33: Kg Ref | I33: Kg Ref | J33: =F6 -> 75 | K33: =SUM(K20:K32) -> 5463 | L33: =SUM(L20:L29) -> 43.67106 | P33: Sodio hipertensos | R33: <1500mg
B35: REQUERIMIENTO FINAL
B37: Kcal | C37: Prot | D37: Grasa | E37: GS | F37: GM | G37: GP | H37: COL | I37: CHOS | J37: Fibra
B38: =K32 -> 2731.5 | C38: =J20 -> 127.5 | D38: =J23 -> 75.875 | E38: =N23 -> 30.35 | F38: =N25 -> 15.175 | G38: =N27 -> 30.35 | H38: =N29 -> 200 | I38: =J30 -> 384.65625 | J38: =N32 -> 14
B40: FÓRMULA SINTÉTICA DESARROLLADA
B42: Grupo de alimentos | H42: Porciones | I42: Kcal | J42: Prot | K42: Grasa | L42: GS | M42: GM | N42: GP | O42: COL | P42: CHOS | Q42: FD | R42: Calcio (mg) | S42: P (mg) | T42: Fe (mg) | U42: Na (mg) | V42: K (mg) | W42: Mg (mg) | X42: Zn (mg) | Y42: Cu (mg) | Z42: Mn (mg) | AA42: Vit A (ER) | AB42: Tiamina (mg) | AC42: Riboflavina (mg) | AD42: Niacina (mg) | AE42: Ac, Pantotenico (mg) | AF42: Priridox. (mg) | AG42: Acido Folico (ug) | AH42: Vit B12 (ug) | AI42: Vit C (mg)
B43: Leches enteras frescas y fermentadas | H43: 3 | I43: =(J43*4)+(K43*9)+(P43*4) -> 139.1 | J43: 6.7 | K43: 6.7 | L43: 4.4 | M43: 1.95 | N43: 0.49 | O43: 26 | P43: 13 | Q43: 0 | R43: 236 | S43: 173 | T43: 0.2 | U43: 96 | V43: 330 | W43: 25 | X43: 0.89 | Y43: 0.03 | Z43: 0.01 | AA43: 73 | AB43: 0.08 | AC43: 0.34 | AD43: 0.3 | AE43: 0.67 | AF43: 0.08 | AG43: 10 | AH43: 0.65 | AI43: 3
B44: Leches semidescremadas frescas y fermentadas | I44: =(J44*4)+(K44*9)+(P44*4) -> 94.5 | J44: 5.4 | K44: 2.1 | L44: 0.87 | M44: 0.54 | N44: 0.35 | O44: 5 | P44: 13.5 | Q44: 0.8 | R44: 153 | S44: 143 | T44: 0.4 | U44: 72 | V44: 268 | W44: 25 | X44: 1.24 | Y44: 0.06 | Z44: 0.11 | AA44: 76 | AB44: 0.12 | AC44: 0.25 | AD44: 0.2 | AE44: 0.41 | AF44: 0.06 | AG44: 8 | AH44: 0.5 | AI44: 4
B45: Leches descremadas frescas y fermentadas | I45: =(J45*4)+(K45*9)+(P45*4) -> 82.3 | J45: 9 | K45: 0.7 | L45: 0.45 | M45: 0.18 | N45: 0.03 | O45: 6 | P45: 10 | Q45: 0 | R45: 256 | S45: 214 | T45: 0.1 | U45: 101 | V45: 340 | W45: 24 | X45: 1.05 | Y45: 0.02 | Z45: 0.01 | AA45: 89 | AB45: 0.08 | AC45: 0.33 | AD45: 0.2 | AE45: 0.79 | AF45: 0.08 | AG45: 14 | AH45: 0.84 | AI45: 2
B46: Leches frescas y fermentadas enteras altas en calorías y azucares | I46: =(J46*4)+(K46*9)+(P46*4) -> 170.7 | J46: 6.4 | K46: 5.9 | L46: 3.8 | M46: 1.91 | N46: 0.63 | O46: 22 | P46: 23 | Q46: 0.4 | R46: 258 | S46: 169 | T46: 0.3 | U46: 115 | V46: 334 | W46: 27 | X46: 1.03 | Y46: 0.05 | Z46: 0.04 | AA46: 45 | AB46: 0.08 | AC46: 0.37 | AD46: 0.2 | AE46: 0.73 | AF46: 0.08 | AG46: 13 | AH46: 0.76 | AI46: 3
B47: Sustitutos | H47: 4 | I47: =(J47*4)+(K47*9)+(P47*4) -> 77.1 | J47: 5.8 | K47: 5.5 | L47: 2.91 | M47: 1.94 | N47: 0.41 | O47: 40 | P47: 1.1 | Q47: 0 | R47: 95 | S47: 85 | T47: 1.1 | U47: 211 | V47: 52 | W47: 6 | X47: 0.65 | Y47: 0.03 | Z47: 0.01 | AA47: 45 | AB47: 0.04 | AC47: 0.1 | AD47: 0.4 | AE47: 0.16 | AF47: 0.05 | AG47: 4 | AH47: 0.72 | AI47: 0
B48: Carnes magras crudas y proteínas texturizada | H48: 3 | I48: =(J48*4)+(K48*9)+(P48*4) -> 108.3 | J48: 19.1 | K48: 3.1 | L48: 0.92 | M48: 1.16 | N48: 0.53 | O48: 50 | P48: 1 | Q48: 0.3 | R48: 22 | S48: 191 | T48: 1.5 | U48: 72 | V48: 325 | W48: 28 | X48: 1.81 | Y48: 0.11 | Z48: 0.12 | AA48: 7 | AB48: 0.19 | AC48: 0.18 | AD48: 5.6 | AE48: 0.78 | AF48: 0.35 | AG48: 15 | AH48: 2.39 | AI48: 1
B49: Carnes crudas altas en lípidos | I49: =(J49*4)+(K49*9)+(P49*4) -> 138.7 | J49: 15.6 | K49: 7.9 | L49: 2.51 | M49: 3.3 | N49: 1.25 | O49: 137 | P49: 1.3 | Q49: 0 | R49: 37 | S49: 186 | T49: 2.5 | U49: 101 | V49: 234 | W49: 20 | X49: 1.87 | Y49: 0.47 | Z49: 0.09 | AA49: 1515 | AB49: 0.07 | AC49: 0.53 | AD49: 4.4 | AE49: 1.67 | AF49: 0.27 | AG49: 87 | AH49: 10.58 | AI49: 6
...

Sheet Pediatría
B2: EVALUACIÓN Y PLANEACIÓN NUTRICIONAL DEL PACIENTE PEDIÁTRICO
B4: EVALUACIÓN ANTROPOMÉTRICA | E4: Área muscular y Área grasa HOMBRES | P4: Área muscular y Área grasa MUJERES
B5: Nombre | L5: Mujer
B6: Apellido
B7: Identificación | L7: Peso/talla
B8: Sexo | C8: Mujer | L8: Obesidad
B9: Edad años | L9: Sobrepeso
B10: Peso kg | L10: Riesgo sobrepeso
B11: Talla/Longitud cm | L11: Adecuado
B12: Talla/Longitud m | C12: =C11/100 -> 0 | L12: Riesgo desnutricion aguda
B13: Antropometria Braquial | L13: Desnutricion aguda moderada
B14: Perimetro brazo mm | L14: Desnutricion aguda severa
B15: Pliegue tricipital mm | L15: Talla/Edad <5
B16: Pliegue subescapular mm | L16: Adecuado
B17: Perímetro Muscular Brazo mm | C17: =C14-(3.14159*C15) -> 0 | L17: Riesgo talla baja
B18: Área Muscular del Brazo mm2 | C18: =(C17^2)/(4*3.14159) -> 0 | L18: Retraso en talla
B19: Percentil AMB
B20: Clasificación AMB mm2 | C20: =IF(C19=L35,"Franco agotamiento de la reserva muscular",IF(C19=L36,"Sugiere agotamiento de la reserva muscular",IF(C19=L37,"Adecuada reserva muscular",IF(C19=L38,"Buena reserva muscular","Introduzca percentil AMB")))) -> Introduzca percentil AMB | L20: Perimetro cef
B21: Area Total del Brazo mm2 | C21: =(3.14159/4)*((C14/3.14159)^2) -> 0 | L21: Riesgo neurodesarrollo
B22: Area Grasa del Brazo mm2 | C22: =C21-C18 -> 0 | L22: Adecuado
B23: Percentil AGB | E23: Adiposidad HOMBRES | P23: Adiposidad MUJERES
B24: Clasificación AGB mm2 | C24: =IF(C23=L40,"Franco agotamiento de la reserva energetica",IF(C23=L41,"Sugiere agotamiento de la reserva energetica",IF(C23=L42,"Reserva energetica adecuada",IF(C23=L43,"Alta reserva energetica asociada a sobrepeso",IF(C23=L44,"Sugiere obesidad","Introduzca percentil AGB"))))) -> Introduzca percentil AGB | L24: Talla/Edad >5
B25: Adiposidad | C25: =C15+C16 -> 0 | L25: Adecuado
B26: Percentil Adiposidad | L26: Riesgo retraso en talla
B27: Clasificación Adiposidad | C27: =IF(C26=L46,"Grasa muy baja",IF(C26=L47,"Grasa baja",IF(C26=L48,"Grasa adecuada",IF(C26=L49,"Exceso de grasa",IF(C26=L50,"Obesidad","Introduzca percentil de adiposidad"))))) -> Introduzca percentil de adiposidad | L27: Talla baja para edad
L28: IMC
B29: RESULTADOS < 5 AÑOS | L29: Obesidad
B30: Peso/Talla pZ | L30: Sobrepeso
B31: Peso/Talla Clasificación | C31: =IF(C30>3,"Obesidad",IF(AND(C30>2,C30<=3),"Sobrepeso",IF(AND(C30>1,C30<=2),"Riesgo de sobrepeso",IF(AND(C30>=-1,C30<=1),"Peso adecuado para la talla",IF(AND(C30>=-2,C30<-1),"Riesgo de desnutricion aguda",IF(AND(C30<-2,C30>=-3),"Desnutricion aguda moderada","Desnutricion aguda severa")))))) -> Peso adecuado para la talla | L31: Adecuado
B32: Talla/Edad pZ | L32: Riesgo delgadez
B33: Talla/Edad Clasificación | C33: =IF(C32>=-1,"Talla adecuada para la edad",IF(AND(C32>=-2,C32<-1),"Riesgo de talla baja","Retraso en talla")) -> Talla adecuada para la edad | L33: Delgadez
B34: Perim Cefalico pZ | L34: Percentiles
B35: Perim Cefalico Clasificación | C35: =IF(AND(C34>=-2,C34<=2),"Normal","Riesgo neurodesarrollo") -> Normal | L35: <5
B36: RESULTADOS 5-17 AÑOS | L36: 5-25
B37: Talla/Edad pZ | L37: 25-75
B38: Talla/Edad Clasificación | C38: =IF(C37>=-1,"Talla adecuada para la edad",IF(AND(C37>=-2,C37<-1),"Riesgo de retraso en talla","Retraso en talla")) -> Talla adecuada para la edad | L38: >75
B39: IMC | C39: =F56 -> #DIV/0!
B40: IMC/Edad pZ | L40: <5
B41: IMC/Edad Clasificación | C41: =IF(C40>2,"Obesidad",IF(AND(C40>1,C40<=2),"Sobrepeso",IF(AND(C40>=-1,C40<=1),"Adecuado",IF(AND(C40>=-2,C40<-1),"Riesgo delgadez","Delgadez")))) -> Adecuado | L41: 5-25
L42: 25-75
...

Sheet Gestante
B2: ESTIMACIÓN Y EVALUACIÓN DE LA GANANCIA
B4: Ganancia de peso esperada según trimestre de gestación
C5: IMC Atalah | D5: Ganancia Total | E5: 1er trimestre | F5: Promedio | G5: 2do y 3er trim | H5: Promedio | I5: % Peso
E6: sem 0 - 13 | F6: g/semana | G6: sem 14 - 40 | H6: g/semana | I6: Total
B7: Bajo peso | C7: <20 | D7: 12kg - 18kg | E7: 2,5kg | F7: 192,3g | G7: 400g - 600g | H7: 500g | I7: 30%
B8: Normo peso | C8: 20-25 | D8: 10kg - 13kg | E8: 1,5kg | F8: 115,4g | G8: 330g - 430g | H8: 400g | I8: 20%
B9: Sobrepeso | C9: 25-30 | D9: 7kg - 10kg | E9: 0,9kg | F9: 69,2g | G9: 230g - 330g | H9: 300g | I9: 15%
B10: Obesidad | C10: >30 | D10: 6kg - 7kg | E10: - | F10: - | G10: 200g - 230g | H10: 200g | I10: 15%
B12: Nombre | E12: Evaluacion de la ganancia | H12: NOTA: Usar ajustes para semana >13
B13: Identificación | E13: Semana gestacional
B14: Edad | E14: Peso kg
B15: Peso preg kg | E15: Debió ganar Kg | F15: =IF(F13<14,((C20/13)*F13),(C20+((C21/27)*(F13-13)))) -> #DIV/0!
B16: Estatura m | E16: Ganancia presentada | F16: =F14-C15 -> 0
B17: IMC | C17: =(C15/(C16*C16)) -> #DIV/0! | E17: IMC gestacional | F17: =(F14/(C16*C16)) -> #DIV/0!
B18: Clasificacion | C18: =IF(C17<20,"Bajo",IF(AND(C17>=20,C17<25),"Normal",IF(AND(C17>=25,C17<30),"Sobrepeso","obesidad"))) -> #DIV/0!
B19: Estimacion de la ganancia | E19: Ajuste 1 | H19: Ajuste 1
B20: Kg Sem 0 - 13 | C20: =IF(C17<20,"2,5",IF(AND(C17>=18.5,C17<25),"1,5",IF(AND(C17>=25,C17<30),"0,9","0"))) -> #DIV/0! | E20: Objetivo x semana g | H20: Objetivo x semana g | I20: =F20
B21: Kg Sem 14 - 40 | C21: =IF(C17<20,"13,5",IF(AND(C17>=18.5,C17<25),"10,8",IF(AND(C17>=25,C17<30),"8,1","5,4"))) -> #DIV/0! | E21: Evaluacion de la ganancia | H21: Evaluac ganancia absoluta | K21: AJUSTE 1 RESULTADO en Kg | T21: =F13 | U21: =F17 -> #DIV/0!
B22: Total kg | C22: =(C21+C20) -> #DIV/0! | E22: Semana gestacional | H22: Semana gestacional | I22: =F22 | K22: Ganancia esperada entre semana | N22: =F13 | O22: y | P22: =F22 | Q22: : | R22: =F24 -> 0 | T22: =F22 | U22: =F26 -> #DIV/0!
B23: % Peso pregestacion | E23: Peso kg | H23: Peso kg | I23: =F23 | K23: Ganancia presentada entre semana | N23: =N22 | O23: y | P23: =P22 | Q23: : | R23: =F25 -> 0 | T23: =F31 | U23: =F35 -> #DIV/0!
B24: Total kg | C24: =IF(C17<20,(C15 *0.3),IF(AND(C17>=18.5,C17<25),(C15*0.2),IF(AND(C17>=25,C17<30),(C27*0.15),(C27*0.15)))) -> #DIV/0! | E24: Debió ganar Kg | F24: =(F20/1000)*(F22-F13) -> 0 | H24: Debió ganar Kg | I24: =IF(I22<14,(C20/13)*I22,C20+((C21/27)*(I22-13))) -> #DIV/0! | K24: Ganancia esperada hasta semana | N24: =P23 | O24: : | P24: =I24 -> #DIV/0! | T24: =F40 | U24: =F44 -> #DIV/0!
B25: En exceso de peso | E25: Ganancia presentada | F25: =F23-F14 -> 0 | H25: Ganancia presentada | I25: =F23-C15 -> 0 | K25: Ganancia absoluta hasta semana | N25: =P23 | O25: : | P25: =I25 -> 0
B26: IMC deseado | E26: IMC gestacional | F26: =(F23/(C16*C16)) -> #DIV/0! | H26: IMC gestacional | I26: =(F23/(C16*C16)) -> #DIV/0!
B27: Peso saludble | C27: =(C26*(C16*C16)) -> 0
B28: Antropometría Braquial | E28: Ajuste 2 | H28: Ajuste 2
B29: Perímetro brazo mm | E29: Objetivo x semana g | H29: Objetivo x semana g | I29: =F29
B30: Plig tricipital mm | E30: Evaluacion de la ganancia | H30: Evaluac ganancia absoluta | K30: AJUSTE 2 RESULTADO en Kg | T30: <5 | U30: <5
B31: Plig subescap mm | E31: Semana gestacional | H31: Semana gestacional | I31: =F31 | K31: Ganancia esperada entre semana | N31: =F22 | O31: y | P31: =F31 | Q31: : | R31: =F33 -> 0 | T31: 5-25 | U31: 5-25
B32: Perím Musc Brazo mm | C32: =C29-(3.14159*C30) -> 0 | E32: Peso kg | H32: Peso kg | I32: =F32 | K32: Ganancia presentada entre semana | N32: =N31 | O32: y | P32: =P31 | Q32: : | R32: =F34 -> 0 | T32: 25-75 | U32: 25-75
B33: Área Mus Brazo mm2 | C33: =(C32^2)/(4*3.14159) -> 0 | E33: Debió ganar Kg | F33: =(F29/1000)*(F31-F22) -> 0 | H33: Debió ganar Kg | I33: =IF(I31<14,(C20/13)*I31,C20+((C21/27)*(I31-13))) -> #DIV/0! | K33: Ganancia esperada hasta semana | N33: =P32 | O33: : | P33: =I33 -> #DIV/0! | T33: >75 | U33: 75-95
B34: Percentil AMB | E34: Ganancia presentada | F34: =F32-F23 -> 0 | H34: Ganancia presentada | I34: =F32-C15 -> 0 | K34: Ganancia absoluta hasta semana | N34: =P32 | O34: : | P34: =I34 -> 0 | U34: >95
B35: Clasificación AMB mm2 | C35: =IF(C34=T30,"Franco agotamiento de la reserva muscular",IF(C34=T31,"Sugiere agotamiento de la reserva muscular",IF(C34=T32,"Adecuada reserva muscular",IF(C34=T33,"Buena reserva muscular","Introduzca percentil AMB")))) -> Introduzca percentil AMB | E35: IMC gestacional | F35: =(F32/(C16*C16)) -> #DIV/0! | H35: IMC gestacional | I35: =(F32/(C16*C16)) -> #DIV/0!
B37: Área Total del Brazo mm2 | C37: =(3.14159/4)*((C29/3.14159)^2) -> 0 | E37: Ajuste 3 | H37: Ajuste 3
B38: Área Grasa del Brazo mm2 | C38: =C37-C33 -> 0 | E38: Objetivo x semana g | H38: Objetivo x semana g | I38: =F38
B39: Percentil AGB | E39: Evaluacion de la ganancia | H39: Evaluac ganancia absoluta | K39: AJUSTE 3 RESULTADO en Kg
B40: Clasificación AGB mm2 | C40: =IF(C39=U30,"Franco agotamiento de la reserva energetica",IF(C39=U31,"Sugiere agotamiento de la reserva energetica",IF(C39=U32,"Reserva energetica adecuada",IF(C39=U33,"Alta reserva energetica asociada a sobrepeso",IF(C39=U34,"Sugiere obesidad","Introduzca percentil AGB"))))) -> Introduzca percentil AGB | E40: Semana gestacional | H40: Semana gestacional | I40: =F40 | K40: Ganancia esperada entre semana | N40: =F31 | O40: y | P40: =F40 | Q40: : | R40: =F42 -> 0
E41: Peso kg | H41: Peso kg | I41: =F41 | K41: Ganancia presentada entre semana | N41: =N40 | O41: y | P41: =P40 | Q41: : | R41: =F43 -> 0
E42: Debió ganar Kg | F42: =(F38/1000)*(F40-F31) -> 0 | H42: Debió ganar Kg | I42: =IF(I40<14,(C20/13)*I40,C20+((C21/27)*(I40-13))) -> #DIV/0! | K42: Ganancia esperada hasta semana | N42: =P41 | O42: : | P42: =I42 -> #DIV/0!
E43: Ganancia presentada | F43: =F41-F32 -> 0 | H43: Ganancia presentada | I43: =F41-C15 -> 0 | K43: Ganancia absoluta hasta semana | N43: =P41 | O43: : | P43: =I43 -> 0
E44: IMC gestacional | F44: =(F41/(C16*C16)) -> #DIV/0! | H44: IMC gestacional | I44: =(F41/(C25*C25)) -> #DIV/0!
...

Sheet Ges Adoles
B2: ESTIMACIÓN Y EVALUACIÓN DE LA GANANCIA EN GESTANTE ADOLESCENTE
B4: Ganancia de peso esperada por trimestre
C5: Total | D5: 1er trimestre | E5: Promedio | F5: 2do y 3er trim | G5: % P, pregest
D6: sem 0 - 13 | E6: g/semana | F6: sem 14 - 40 | G6: Total
B7: Bajo peso | C7: 12,6kg - 18kg | D7: 2,25kg | E7: 173g | F7: >450g | G7: 35%
B8: Normo peso | C8: 11,2kg - 15,7kg | D8: 1,3kg | E8: 100g | F8: >450g | G8: 30%
B9: Sobrepeso | C9: 6,7kg - 11,3kg | D9: 0,9kg | E9: 69g | F9: >297g | G9: 20%
B10: Obesidad | C10: 6,7kg | D10: 0,675kg | E10: 52g | F10: >225g | G10: 20%
B12: Nombre
B13: Identificación | E13: Evaluación de la ganancia | H13: NOTA: Usar ajustes para semana >13
B14: Edad | E14: Semana gestacional
B15: Peso preg kg | E15: Peso kg
B16: Estatura m | E16: Debió ganar Kg | F16: =IF(F14<14,((C21/13)*F14),(C21+((C22/27)*(F14-13)))) -> 0
B17: IMC | C17: =(C15/(C16*C16)) -> #DIV/0! | E17: Ganancia presentada | F17: =F15-C15 -> 0
B18: Puntaje Z | E18: IMC gestacional | F18: =(F15/(C16*C16)) -> #DIV/0!
B19: Clasificación | C19: =IF(C18<-2,"Delgadez",IF(AND(C18>=-2,C18<-1),"Riesgo delgadez",IF(AND(C18>=-1,C18<=1),"Adecuado",IF(AND(C18>1,C18<=2),"Sobrepeso","obesidad")))) -> Adecuado
B20: Estimación de la ganancia | E20: Ajuste 1 | H20: Ajuste 1
B21: Kg Sem 0 - 13 | C21: =IF(C18<-1,"2,25",IF(AND(C18>=-1,C18<=1),"1,3",IF(AND(C18>1,C18<=2),"0,9","0,675"))) -> 1,3 | E21: Objetivo x semana g | H21: Objetivo x semana g | I21: =F21
B22: Kg Sem 14 - 40 | C22: =IF(C18<-1,"12,15",IF(AND(C18>=-1,C18<=1),"12,15",IF(AND(C18>1,C18<=2),"8","6"))) -> 12,15 | E22: Evaluación de la ganancia | H22: Evaluac ganancia absoluta | K22: AJUSTE 1 RESULTADO en Kg
B23: Total kg | C23: =(C22+C21) -> 13.45 | E23: Semana gestacional | H23: Semana gestacional | I23: =F23 | K23: Ganancia esperada entre semana | N23: =F14 | O23: y | P23: =F23 | Q23: : | R23: =F25 -> 0
B24: % Peso pregestación | E24: Peso kg | H24: Peso kg | I24: =F24 | K24: Ganancia presentada entre semana | N24: =N23 | O24: y | P24: =P23 | Q24: : | R24: =F26 -> 0
B25: Total kg | C25: =IF(C18<-1,(C15 *0.35),IF(AND(C18>=-1,C18<=1),(C15*0.3),IF(AND(C18>1,C18<=2),(C28*0.2),(C28*0.2)))) -> 0 | E25: Debió ganar Kg | F25: =(F21/1000)*(F23-F14) -> 0 | H25: Debió ganar Kg | I25: =IF(I23<14,(C21/13)*I23,C21+((C22/27)*(I23-13))) -> 0 | K25: Ganancia esperada hasta semana | N25: =P24 | O25: : | P25: =I25 -> 0
B26: En exceso de peso | E26: Ganancia presentada | F26: =F24-F15 -> 0 | H26: Ganancia presentada | I26: =F24-C15 -> 0 | K26: Ganancia absoluta hasta semana | N26: =P24 | O26: : | P26: =I26 -> 0
B27: IMC deseado | C27: 24 | E27: IMC gestacional | F27: =(F24/(C16*C16)) -> #DIV/0! | H27: IMC gestacional | I27: =(F24/(C16*C16)) -> #DIV/0!
B28: Peso saludble | C28: =(C27*(C16*C16)) -> 0
E29: Ajuste 2 | H29: Ajuste 2
E30: Objetivo x semana g | H30: Objetivo x semana g | I30: =F30
E31: Evaluación de la ganancia | H31: Evaluac ganancia absoluta | K31: AJUSTE 2 RESULTADO en Kg
E32: Semana gestacional | H32: Semana gestacional | I32: =F32 | K32: Ganancia esperada entre semana | N32: =F23 | O32: y | P32: =F32 | Q32: : | R32: =F34 -> 0
E33: Peso kg | H33: Peso kg | I33: =F33 | K33: Ganancia presentada entre semana | N33: =N32 | O33: y | P33: =P32 | Q33: : | R33: =F35 -> 0
E34: Debió ganar Kg | F34: =(F30/1000)*(F32-F23) -> 0 | H34: Debió ganar Kg | I34: =IF(I32<14,(C21/13)*I32,C21+((C22/27)*(I32-13))) -> 0 | K34: Ganancia esperada hasta semana | N34: =P33 | O34: : | P34: =I34 -> 0
E35: Ganancia presentada | F35: =F33-F24 -> 0 | H35: Ganancia presentada | I35: =F33-C15 -> 0 | K35: Ganancia absoluta hasta semana | N35: =P33 | O35: : | P35: =I35 -> 0
E36: IMC gestacional | F36: =(F33/(C16*C16)) -> #DIV/0! | H36: IMC gestacional | I36: =(F33/(C16*C16)) -> #DIV/0!
E38: Ajuste 3 | H38: Ajuste 3
E39: Objetivo x semana g | H39: Objetivo x semana g | I39: =F39
E40: Evaluación de la ganancia | H40: Evaluac ganancia absoluta | K40: AJUSTE 3 RESULTADO en Kg
E41: Semana gestacional | H41: Semana gestacional | I41: =F41 | K41: Ganancia esperada entre semana | N41: =F32 | O41: y | P41: =F41 | Q41: : | R41: =F43 -> 0
E42: Peso kg | H42: Peso kg | I42: =F42 | K42: Ganancia presentada entre semana | N42: =N41 | O42: y | P42: =P41 | Q42: : | R42: =F44 -> 0
E43: Debió ganar Kg | F43: =(F39/1000)*(F41-F32) -> 0 | H43: Debió ganar Kg | I43: =IF(I41<14,(C21/13)*I41,C21+((C22/27)*(I41-13))) -> 0 | K43: Ganancia esperada hasta semana | N43: =P42 | O43: : | P43: =I43 -> 0
E44: Ganancia presentada | F44: =F42-F33 -> 0 | H44: Ganancia presentada | I44: =F42-C24 -> 0 | K44: Ganancia absoluta hasta semana | N44: =P42 | O44: : | P44: =I44 -> 0
...

Sheet Hospitalizado
B2: PACIENTE HOSPITALIZADO
B4: EVALUACIÓN ANTROPOMÉTRICA | E4: GASTO ENERGÉTICO | I4: FACTOR DE ACTIVIDAD
B5: Nombre | E5: Sexo | G5: Hombre | H5: =IF(G5="Hombre",1,0) -> 1 | I5: Inconsciente/Coma | K5: 1
B6: Apellido | E6: Peso Kg | I6: En cama | K6: 1,1 - 1,2
B7: Identificación | E7: Altura cm | I7: Ambulatorio | K7: 1.3
B8: Sexo | C8: Hombre | E8: Edad años | I8: FACTOR DE ESTRÉS
B9: Edad años | E9: Factor actividad | G9: 1 | I9: Cirugía mayor | K9: 1.2
B10: Peso kg | E10: Factor estrés | G10: 1 | I10: Cirugía menor | K10: 1.1
B11: Altura m | E11: Harris y Benedict | I11: Infección leve | K11: 1.2
B12: Altura cm | C12: =C11*100 -> 0 | E12: Requerimiento total | G12: =IF(G5="Hombre",((67.47+(13.75*(G6))+(5*(G7))-(6.78*(G8)))*G9*G10),((655.1+(9.56*(G6))+(1.85*(G7))-(4.68*(G8)))*G9*G10)) -> 67.47 | I12: Infección moderada | K12: 1.5
B13: Estimación Talla | E13: Mifflin y St Jeor | I13: Infección severa | K13: 1.8
B14: Talón rodilla cm | E14: Requerimiento total | G14: =IF(G5="Hombre",(((10*(G6))+(6.25*(G7))-(5*(G8))+5)*G9*G10),(((10*(G6))+(6.25*(G7))-(5*(G8))-161)*G9*G10)) -> 5 | I14: Trauma esqueleto | K14: 1.35
B15: Talla estimada cm | C15: =IF(C8="Hombre",((2.02*C14)-(0.04*C9)+64.19),((1.83*C14)-(0.24*C9)+84.88)) -> 64.19 | E15: Ireton y Jones | I15: Trauma contusión | K15: 1.35
B16: Estimación Peso | E16: Soporte ventilatorio | G16: No | I16: Lesión de cabeza | K16: 1.6
B17: Talón rodilla cm | E17: Obesidad | G17: No | H17: =IF(G17="Sí",1,0) -> 0 | I17: Quemadura 40% | K17: 1.5
B18: Perimetro brazo cm | E18: Trauma | G18: No | H18: =IF(G18="Sí",1,0) -> 0 | I18: Quemadura 100% | K18: 1.96
B19: Perimetro pantorrilla cm | E19: Quemadura | G19: No | H19: =IF(G19="Sí",1,0) -> 0 | I19: Peritonitis | K19: 1,05 - 1,25
B20: Pliegue subescapular mm | E20: Requerimiento total | G20: =IF(G16="Sí",(1925-(10*(G8))+(5*(G6))+(28*H5)+(292*H18)+(851*H19)),(629-(11*(G8))+(25*(G6))-(609*H17))) -> 629 | I20: Cáncer | K20: 1,1 - 1,45
B21: Estimación del peso Kg | C21: =IF(C8="Hombre",((C18*1.73)+(C19*0.98)+(C20*0.37)+(C17*1.16)-81.69),((C18*0.98)+(C19*1.27)+(C20*0.4)+(C17*0.87)-62.35)) -> -81.69 | E21: Método del pulgar
E22: Kcal/kg/Día
B23: PESO SALUDABLE IMC | E23: Requerimiento total | G23: =G22*G6 -> 0 | I23: Para el cálculo de requerimiento SIEMPRE debe colocar factor de actividad y estrés. Calcule el requerimiento con el peso actual en caso de desnutrición; con peso ideal en sobrepeso; y con peso ajustado en obesidad.
B24: Peso kg
B25: Talla m | E25: LÍQUIDOS
B26: IMC | C26: =(C24/(C25*C25)) -> #DIV/0! | E26: cc/kg/día | M26: Referencias
B27: IMC deseado | E27: ml totales | G27: =G26*G6 -> 0 | M27: Estimación talla: Chumlea W, Roche A, Steinbaugh M. Estimating stature from knee height for persons 60-90 years of age. J Am Geriatr Soc 1985; 33: 116-120.
B28: Peso saludable IMC 25-30 | E28: Calcule los líquidos con peso actual idealmente con 30cc a 40cc | M28: Estimación peso: Chumlea WC, Guo S, Roche AF, Steinbaugh ML. Prediction of body weight for the nonambulatory elderly from anthropo – metry. J Am Diet Assoc 1988; 88 (5): 564-568
B29: PS | C29: =(C27*(C25*C25)) -> 0 | M29: Ec Harris y Benedict: Banta, A. M. (1918). Sex and Sex Intergrades in Cladocera. Proceedings of the National Academy of Sciences, 4(12), 373–379. doi:10.1073/pnas.4.12.373
B30: Peso ajustado IMC >30 | M30: Ec Miflin y St Jeor: Am J Clin Nutr 1990; 51: 241-7.
B31: PA | C31: =(C29+(0.25*(C24-C29))) -> 0
B33: NUTRICIÓN PARENTERAL ADULTO
B35: 1. Introduzca las calorías y la cantidad de líquido que va a suministrar al paciente
B37: Peso del paciente (kg)
B38: Calorías totales
B39: Líquidos totales (ml)
B41: 2. Defina el aporte de macro y micronutrientes, guiese por la tabla adjunta
B43: Proteína (g/kg/día) | D43: =F65*4 -> 0 | E43: Requerimientos usuales | K43: =IF(AND(C45<>0, OR(C45<2,C45>5)),"La admon de CHOs debe hacerse con un flujo de 2 – 5 mg/kg/min, un valor menor favorece la gluconeogénesis; un valor mayor excede la capacidad de oxidación lo que causa hiperglicemia, diuresis osmótica y coma hiperosmolar no cetósico","") | O43: La cantidad de lípidos es el resultado de la diferencia del total de calorias, con las calorias de (CHOs + proteína), que se requieren para completar el total de calorias programadas
B44: CHOs (g/kg/día) | D44: =F66*3.4 -> 0 | E44: Proteína (g/kg/día) | G44: 0,8 - 1,8
B45: Flujo metabolico(mg/kg/min) | C45: =(C44*1000)/1440 -> 0 | D45: =C38-(D43+D44) -> 0 | E45: CHOs (g/kg/día) | G45: 3,0 - 7,0
B46: Lípidos (g/kg/día) | C46: =D46/C37 -> #DIV/0! | D46: =D45/(IF(G57="Omegaven 10%",11,10)) -> 0 | E46: Lípidos (g/kg/día) | G46: Estable | I46: 0,7 - 1,3
B47: Sodio (mEq/kg) | G47: Alta demanda energética | I47: 1,5 - 2,5
...

Sheet Deportista
B2: SOMATOCARTA
B4: SOMATOTIPO
B5: Peso kg | N5: CLASIFICACIÓN | R5: =SUM(C30:C35) -> 0
B6: Triceps mm | N6: A. Mesomorfo balanceado
B7: Subescapular mm | N7: B. Endomorfo balanceado
B8: Supraespinal mm | N8: C. Ectomorfo balanceado
B9: Sumatoria | C9: =SUM(C6:C8) -> 0 | N9: D. Mesomorfo-Endomorfo
B10: Corrección proporcionalidad | C10: =C9*(170.18/C11) -> #DIV/0! | N10: E. Mesomorfo-Ectomorfo
B11: Estatura cm | N11: F. Endomorfo-Ectomorfo
B12: Diámetro humero cm | N12: G. Endo-Mesomorfo
B13: Diámetro femur cm | N13: H. Meso-Endomorfo
B14: Perímetro brazo tenso cm | N14: I. Meso-Ectomorfo
B15: Perímetro brazo corregido | C15: =C14-(C6/10) -> 0 | N15: J. Ecto-Mesomorfo
B16: Perímetro pantorrilla cm | N16: K. Ecto-Endomorfo
B17: Pliegue pantorrilla mm | N17: L. Endo-Ectomorfo
B18: Perímetro pantorrilla corregido | C18: =C16-(C17/10) -> 0
B19: HWR | C19: =C11/(C5^0.333) -> #DIV/0!
B20: Componentes
B21: ENDOMORFIA | C21: =(0.1451*C10)-(0.00068*(C10^2))+(0.0000014*(C10^3))-0.7182 -> #DIV/0!
B22: MESOMORFIA | C22: =(0.858*C12)+(0.601*C13)+(0.188*C15)+(0.161*C18)-(0.131*C11)+4.5 -> 4.5
B23: ECTOMORFIA | C23: =IF(C19>=40.75,((C19*0.732)-28.58),IF(AND(C19>38.25,C19<40.75),((C19*0.463)-17.63),0.1)) -> #DIV/0!
B24: Coordenadas
B25: X | C25: =C23-C21 -> #DIV/0!
B26: Y | C26: =(2*C22)-(C23+C21) -> #DIV/0!
B28: % Grasa Yuhasz
B29: Sexo | C29: Hombre
B30: Triceps mm | C30: =C6
B31: Subescapular mm | C31: =C7
B32: Supraespinal mm | C32: =C8
B33: Pantorrilla mm | C33: =C17
B34: Abdominal mm
B35: Muslo medio mm
B36: % Grasa | C36: =IF(C29="Hombre",((0.1051*R5)+2.585),((0.1548*R5)+3.588)) -> 2.585
B37: Peso graso kg | C37: =((C5*C36)/100) -> 0
B38: Masa libre de grasa kg | C38: =C5-C37 -> 0
B39: Índice Sustancia Corporal Activa | C39: =(C38*100000)/(C11^3) -> #DIV/0!
B40: Clasificación AKS | C40: =IF(C39<0.99,"Deficiente masa muscular",IF(AND(C39>=1,C39<=1.12),"Adecuada masa muscular","Excelente masa muscular")) -> #DIV/0!
B41: Peso optimo
B42: % grasa esperado
B43: Peso optimo Kg | C43: =C38/(1-(C42/100)) -> 0
...

Sheet F. Desarrollada
B2: FÓRMULA SINTÉTICA DESARROLLADA
B4: Grupo de alimentos | C4: Porciones | D4: Kcal | E4: Prot | F4: Grasa | G4: GS | H4: GM | I4: GP | J4: COL | K4: CHOS | L4: FD | M4: Calcio (mg) | N4: P (mg) | O4: Fe (mg) | P4: Na (mg) | Q4: K (mg) | R4: Mg (mg) | S4: Zn (mg) | T4: Cu (mg) | U4: Mn (mg) | V4: Vit A (ER) | W4: Tiamina (mg) | X4: Riboflavina (mg) | Y4: Niacina (mg) | Z4: Ac, Pantotenico (mg) | AA4: Priridox. (mg) | AB4: Acido Folico (ug) | AC4: Vit B12 (ug) | AD4: Vit C (ug)
B5: Leches enteras frescas y fermentadas | D5: =(E5*4)+(F5*9)+(K5*4) -> 139.1 | E5: 6.7 | F5: 6.7 | G5: 4.4 | H5: 1.95 | I5: 0.49 | J5: 26 | K5: 13 | L5: 0 | M5: 236 | N5: 173 | O5: 0.2 | P5: 96 | Q5: 330 | R5: 25 | S5: 0.89 | T5: 0.03 | U5: 0.01 | V5: 73 | W5: 0.08 | X5: 0.34 | Y5: 0.3 | Z5: 0.67 | AA5: 0.08 | AB5: 10 | AC5: 0.65 | AD5: 3
B6: Leches semidescremadas frescas y fermentadas | D6: =(E6*4)+(F6*9)+(K6*4) -> 94.5 | E6: 5.4 | F6: 2.1 | G6: 0.87 | H6: 0.54 | I6: 0.35 | J6: 5 | K6: 13.5 | L6: 0.8 | M6: 153 | N6: 143 | O6: 0.4 | P6: 72 | Q6: 268 | R6: 25 | S6: 1.24 | T6: 0.06 | U6: 0.11 | V6: 76 | W6: 0.12 | X6: 0.25 | Y6: 0.2 | Z6: 0.41 | AA6: 0.06 | AB6: 8 | AC6: 0.5 | AD6: 4
B7: Leches descremadas frescas y fermentadas | D7: =(E7*4)+(F7*9)+(K7*4) -> 82.3 | E7: 9 | F7: 0.7 | G7: 0.45 | H7: 0.18 | I7: 0.03 | J7: 6 | K7: 10 | L7: 0 | M7: 256 | N7: 214 | O7: 0.1 | P7: 101 | Q7: 340 | R7: 24 | S7: 1.05 | T7: 0.02 | U7: 0.01 | V7: 89 | W7: 0.08 | X7: 0.33 | Y7: 0.2 | Z7: 0.79 | AA7: 0.08 | AB7: 14 | AC7: 0.84 | AD7: 2
B8: Leches frescas y fermentadas enteras altas en calorías y azucares | D8: =(E8*4)+(F8*9)+(K8*4) -> 170.7 | E8: 6.4 | F8: 5.9 | G8: 3.8 | H8: 1.91 | I8: 0.63 | J8: 22 | K8: 23 | L8: 0.4 | M8: 258 | N8: 169 | O8: 0.3 | P8: 115 | Q8: 334 | R8: 27 | S8: 1.03 | T8: 0.05 | U8: 0.04 | V8: 45 | W8: 0.08 | X8: 0.37 | Y8: 0.2 | Z8: 0.73 | AA8: 0.08 | AB8: 13 | AC8: 0.76 | AD8: 3
B9: Leches frescas, fermentadas y productos lácteos menores de 2 años | D9: =(E9*4)+(F9*9)+(K9*4) -> 50.7 | E9: 2.9 | F9: 3.1 | G9: 2.01 | H9: 0.96 | I9: 0.18 | J9: 12 | K9: 2.8 | L9: 0 | M9: 93 | N9: 62 | O9: 0.1 | P9: 57 | Q9: 57 | R9: 6 | S9: 0.38 | T9: 0.01 | U9: 0 | V9: 36 | W9: 0.01 | X9: 0.08 | Y9: 0.1 | Z9: 0.12 | AA9: 0.02 | AB9: 2 | AC9: 0.2 | AD9: 0
B10: Sustitutos | D10: =(E10*4)+(F10*9)+(K10*4) -> 77.1 | E10: 5.8 | F10: 5.5 | G10: 2.91 | H10: 1.94 | I10: 0.41 | J10: 40 | K10: 1.1 | L10: 0 | M10: 95 | N10: 85 | O10: 1.1 | P10: 211 | Q10: 52 | R10: 6 | S10: 0.65 | T10: 0.03 | U10: 0.01 | V10: 45 | W10: 0.04 | X10: 0.1 | Y10: 0.4 | Z10: 0.16 | AA10: 0.05 | AB10: 4 | AC10: 0.72 | AD10: 0
B11: Huevo menores de 2 años | D11: =(E11*4)+(F11*9)+(K11*4) -> 52.9 | E11: 4.5 | F11: 3.7 | G11: 1.15 | H11: 1.42 | I11: 0.49 | J11: 180 | K11: 0.4 | L11: 0 | M11: 19 | N11: 64 | O11: 0.6 | P11: 46 | Q11: 46 | R11: 4 | S11: 0.4 | T11: 0.01 | U11: 0.01 | V11: 57 | W11: 0.03 | X11: 0.2 | Y11: 0 | Z11: 0.51 | AA11: 0.05 | AB11: 18 | AC11: 0.43 | AD11: 0
B12: Carnes magras crudas y proteínas texturizada adultos y niños | D12: =(E12*4)+(F12*9)+(K12*4) -> 108.3 | E12: 19.1 | F12: 3.1 | G12: 0.92 | H12: 1.16 | I12: 0.53 | J12: 50 | K12: 1 | L12: 0.3 | M12: 22 | N12: 191 | O12: 1.5 | P12: 72 | Q12: 325 | R12: 28 | S12: 1.81 | T12: 0.11 | U12: 0.12 | V12: 7 | W12: 0.19 | X12: 0.18 | Y12: 5.6 | Z12: 0.78 | AA12: 0.35 | AB12: 15 | AC12: 2.39 | AD12: 1
B13: Carnes magras cocidas menores de 2 años | D13: =(E13*4)+(F13*9)+(K13*4) -> 49.2 | E13: 7.8 | F13: 2 | G13: 0.52 | H13: 0.84 | I13: 0.35 | J13: 21 | K13: 0 | L13: 0 | M13: 7 | N13: 74 | O13: 0.4 | P13: 19 | Q13: 108 | R13: 8 | S13: 0.55 | T13: 0.04 | U13: 0.09 | V13: 5 | W13: 0.1 | X13: 0.07 | Y13: 1.9 | Z13: 0.33 | AA13: 0.09 | AB13: 2 | AC13: 1 | AD13: 0
B14: Carnes crudas altas en lípidos adultos y niños | D14: =(E14*4)+(F14*9)+(K14*4) -> 138.7 | E14: 15.6 | F14: 7.9 | G14: 2.51 | H14: 3.3 | I14: 1.25 | J14: 137 | K14: 1.3 | L14: 0 | M14: 37 | N14: 186 | O14: 2.5 | P14: 101 | Q14: 234 | R14: 20 | S14: 1.87 | T14: 0.47 | U14: 0.09 | V14: 1515 | W14: 0.07 | X14: 0.53 | Y14: 4.4 | Z14: 1.67 | AA14: 0.27 | AB14: 87 | AC14: 10.58 | AD14: 6
B15: Carnes cocidas altas en lípidos menores de 2 años | D15: =(E15*4)+(F15*9)+(K15*4) -> 46.8 | E15: 6.9 | F15: 2 | G15: 0.78 | H15: 0.86 | I15: 0.31 | J15: 79 | K15: 0.3 | L15: 0 | M15: 3 | N15: 57 | O15: 3 | P15: 62 | Q15: 55 | R15: 6 | S15: 1.21 | T15: 0.25 | U15: 0.04 | V15: 620 | W15: 0.02 | X15: 0.29 | Y15: 1.1 | Z15: 0.55 | AA15: 0.09 | AB15: 39 | AC15: 4.29 | AD15: 2
B16: Leguminosas adultos | D16: =(E16*4)+(F16*9)+(K16*4) -> 158.1 | E16: 9.8 | F16: 1.7 | G16: 0.25 | H16: 0.32 | I16: 0.94 | J16: 0 | K16: 25.9 | L16: 7.9 | M16: 50 | N16: 167 | O16: 3.1 | P16: 10 | Q16: 534 | R16: 62 | S16: 1.22 | T16: 0.28 | U16: 0.6 | V16: 10 | W16: 0.2 | X16: 0.09 | Y16: 0.9 | Z16: 0.42 | AA16: 0.16 | AB16: 142 | AC16: 0 | AD16: 4
... B45: Leche materna toma/100ml | D45: =(E45*4)+(F45*9)+(K45*4) -> 71.2 | E45: 1 | F45: 4.4 | G45: 2.01 | H45: 1.66 | I45: 0.5 | J45: 14 | K45: 6.9 | L45: 0 | M45: 32 | N45: 14 | O45: 0 | P45: 17 | Q45: 51 | R45: 3 | S45: 0.17 | T45: 0.05 | U45: 0.03 | V45: 64 | W45: 0.01 | X45: 0.04 | Y45: 0.2 | Z45: 0.22 | AA45: 0.01 | AB45: 5 | AC45: 0.05 | AD45: 5
B46: Suplemento (Introduzca manualmente los nutrientes por porción)
B49: Grupo de alimentos | C49: Porciones | D49: Kcal | E49: Prot | F49: Grasa | G49: GS | H49: GM | I49: GP | J49: COL | K49: CHOS | L49: FD | M49: Calcio (mg) | N49: P (mg) | O49: Fe (mg) | P49: Na (mg) | Q49: K (mg) | R49: Mg (mg) | S49: Zn (mg) | T49: Cu (mg) | U49: Mn (mg) | V49: Vit A (ER) | W49: Tiamina (mg) | X49: Riboflavina (mg) | Y49: Niacina (mg) | Z49: Ac, Pantotenico (mg) | AA49: Priridox. (mg) | AB49: Acido Folico (ug) | AC49: Vit B12 (ug) | AD49: Vit BC (ug)
B50: Leches enteras frescas y fermentadas | C50: =C5 | D50: =(D5*C5) -> 0 | E50: =(E5*C5) -> 0 | F50: =(F5*C5) -> 0 | G50: =(G5*C5) -> 0 | H50: =(H5*C5) -> 0 | I50: =(I5*C5) -> 0 | J50: =(J5*C5) -> 0 | K50: =(K5*C5) -> 0 | L50: =(L5*C5) -> 0 | M50: =(M5*C5) -> 0 | N50: =(N5*C5) -> 0 | O50: =(O5*C5) -> 0 | P50: =(P5*C5) -> 0 | Q50: =(Q5*C5) -> 0 | R50: =(R5*C5) -> 0 | S50: =(S5*C5) -> 0 | T50: =(T5*C5) -> 0 | U50: =(U5*C5) -> 0 | V50: =(V5*C5) -> 0 | W50: =(W5*C5) -> 0 | X50: =(X5*C5) -> 0 | Y50: =(Y5*C5) -> 0 | Z50: =(Z5*C5) -> 0 | AA50: =(AA5*C5) -> 0 | AB50: =(AB5*C5) -> 0 | AC50: =(AC5*C5) -> 0 | AD50: =(AD5*C5) -> 0
B51: Leches semidescremadas frescas y fermentadas | C51: =C6 | D51: =(D6*C6) -> 0 | E51: =(E6*C6) -> 0 | F51: =(F6*C6) -> 0 | G51: =(G6*C6) -> 0 | H51: =(H6*C6) -> 0 | I51: =(I6*C6) -> 0 | J51: =(J6*C6) -> 0 | K51: =(K6*C6) -> 0 | L51: =(L6*C6) -> 0 | M51: =(M6*C6) -> 0 | N51: =(N6*C6) -> 0 | O51: =(O6*C6) -> 0 | P51: =(P6*C6) -> 0 | Q51: =(Q6*C6) -> 0 | R51: =(R6*C6) -> 0 | S51: =(S6*C6) -> 0 | T51: =(T6*C6) -> 0 | U51: =(U6*C6) -> 0 | V51: =(V6*C6) -> 0 | W51: =(W6*C6) -> 0 | X51: =(X6*C6) -> 0 | Y51: =(Y6*C6) -> 0 | Z51: =(Z6*C6) -> 0 | AA51: =(AA6*C6) -> 0 | AB51: =(AB6*C6) -> 0 | AC51: =(AC6*C6) -> 0 | AD51: =(AD6*C6) -> 0
